<mujoco model="jaco2">
    <compiler angle="radian" meshdir="meshes" balanceinertia="true"/>

    <asset>
        <!-- arm models -->

        <mesh file="front_alu_3.STL"/>
        <mesh file="front_alu_1.STL"/>
        <mesh file="back_alu_1.STL"/>
        <mesh file="back_alu_2.STL"/>
        <mesh file="battery.STL"/>
        <mesh file="logic.STL"/>
        <mesh file="logic2.STL"/>
        <mesh file="electronics.STL"/>
        <mesh file="encoder.STL"/>
        <mesh file="gearbox_1.STL"/>
        <mesh file="gearbox_3.STL"/>
        <mesh file="gearbox1_spacer.STL"/>
        <mesh file="gearbox2.STL"/>
        <mesh file="lower_leg.STL"/>
        <mesh file="upper_leg_belt.STL"/>
        <mesh file="upper_leg.STL"/>
        <mesh file="spacer_spine.STL"/>


        <material name="aluminium" rgba="0.35 0.35 0.35 1"/>
        <material name="petg" rgba="0.7 0.7 0.75 1"/>
        <material name="carbon" rgba="0.05 0.05 0.05 1"/>
        <material name="silicone" rgba="0.612 0.11 0.42 1"/>
        <material name="pcb" rgba="0.253 0.41 0.202 1"/>

    </asset>

    <worldbody>

 <light directional="true" pos="-0.5 0 3" dir="0 0 -1" />
		            <geom type="box" size="0.01 0.01 0.01" rgba=".9 .9 .9 1"/>
		                <body name = "chassis" pos="0 0 0.4" euler='0 0 0'>



                        <body name="electronics" pos="0 0 0" euler="-3.141592 0 3.141592">
                    <geom name="electronics" type="mesh" mesh="electronics" pos="0 0 0" material="pcb"/>
                    <inertial pos="0.052 0 -0.019" mass="0.217" fullinertia="0.0002606 0.001278 0.001213 0.000004437742 0.0001681 -0.0000333683"/>
                        <body name="front_alu_1" pos="0.141 0 0.004" euler="0 3.141592 0">
                    <geom name="front_alu_1" type="mesh" mesh="front_alu_1" pos="0 0 0" material="aluminium"/>
                    <inertial pos="0.000029 -0.021971 -0.047265" mass="0.086155" fullinertia="0.0003762 0.0005127 0.0002374 0.000000063417 0.000000063417 -0.0001046"/>
                        <body name="logic" pos="-0.0016 0.018 -0.0058" euler="1.5707963 0 1.5707963">
                    <geom name="logic" type="mesh" mesh="logic" pos="0 0 0" material="pcb"/>
                    <inertial pos="0.037 -0.0692 -0.0318" mass="0.215" fullinertia="0.001698 0.0006263 0.001756 0.0005497 0.0002479 -0.0004718"/>
                        <body name="front_alu_3" pos="0.023 -0.072 0.06" euler="0 0 -1.5707963">
                    <geom name="front_alu_3" type="mesh" mesh="front_alu_3" pos="0 0 0" material="aluminium" />
                    <inertial pos="0 0.054215 -0.061065" mass="0.124065" fullinertia="0.001253 0.001031 0.0006775 0 0 0.0004275"/>
                        <body name="battery" pos="-0.04 -0.016 -0.048" euler="-1.5707963 0 1.5707963">
                    <geom name="battery" type="mesh" mesh="battery" pos="0 0 0" material="carbon"/>
                    <inertial pos="0.069942 -0.006256 0.035746" mass="0.870023" fullinertia="0.00225 0.007884 0.006258 0.00038 -0.002177 0.0001947"/>
                        </body>
                        </body>
                        </body>
                        </body>
                        </body>

                        <body name="spacer_spine" pos="-0.141 -0.056 -0.006">
                    <geom name="spacer_spine" type="mesh" mesh="spacer_spine" pos="0 0 0" material="petg" euler="0 0 0"/>
                    <inertial pos="0 0 0" mass="0.001" fullinertia="0.00000665976 0.000014054247 0.000014432848 -0.000000796234 -0.000003221775 -0.000000490008"/>

                        <body name="back_alu_1" pos="0.07 -0.026 0.02" euler="1.5707963 0 0">
                    <geom name="back_alu_1" type="mesh" mesh="back_alu_1" pos="0 0 0" material="aluminium"/>
                    <inertial pos="0.061117 -0.071838 -0.030713" mass="0.083888" fullinertia="0.740119405 0.0005197 0.0008841 0.000000003684 0.0001642 -0.000185"/>
                        <body name="back_alu_2" pos="0.07 -0.017 -0.015" euler="-1.5707963 0 -3.141592">
                    <geom name="back_alu_2" type="mesh" mesh="back_alu_2" pos="0 0 0" material="aluminium" />
                    <inertial pos="0.004215 -0.071852 -0.018043" mass="0.057775" fullinertia="0.0004472 0.000054900942 0.0004108 0.000017498098 -0.000003094151 -0.000074908007"/>
                        <body name="logic2" pos="-0.0024 0.0237 -0.007" euler="1.5707963 0 1.5707963">
                    <geom name="logic2" type="mesh" mesh="logic2" pos="0 0 0" material="pcb" />
                    <inertial pos="0.037 -0.0692 -0.0318" mass="0.215" fullinertia="0.001698 0.0006263 0.001756 0.0005497 0.0002479 -0.0004718"/>

                        </body>
                        </body>
                        </body>



                             <!-- leg 0 -->
                        <body name="encoder_0_2" pos="0.1234 -0.11 0.0273" euler="1.570796 3.141592 0">
                    <geom name="encoder_0_2" type="mesh" mesh="encoder" pos="0 0 0" material="pcb" />
                    <inertial pos="0 0 0.006" mass="0.008" fullinertia="0.00000665976 0.000014054247 0.000014432848 -0.000000796234 -0.000003221775 -0.000000490008"/>
                        <body name="gearbox_1_2" pos="0 0 -0.056" euler="0 0 0">
                    <inertial pos="0 0 0.03062" mass="0.549677" fullinertia="0.0008966 0.0008969 0.0005599 -0.000000208093 0.000000039236 -0.000000146242"/>
                    <geom name="gearbox_1_2" type="mesh" mesh="gearbox_1" pos="0 0 0" material="petg"/>
                        <body name="gearbox1_spacer_2" pos="0 0.0 -0.012" euler="0 0 0">
                    <geom name="gearbox1_spacer_2" type="mesh" mesh="gearbox1_spacer" pos="0 0 0" material="petg"/>
                    <inertial pos="0 0 0.006" mass="0.008" fullinertia="0.00000665976 0.000014054247 0.000014432848 -0.000000796234 -0.000003221775 -0.000000490008"/>
                        <body name="spacer_3_2" pos="0.002 0 -0.0003" euler="0 3.141592 0">
                    <geom type="box" size="0.0001 0.00001 0.0001" rgba=".9 .9 .9 1"/>
                    <inertial pos="0 0 0" mass="0.001" fullinertia="0.00000665976 0.000014054247 0.000014432848 -0.000000796234 -0.000003221775 -0.000000490008"/>

                    <joint name="joint0_2" axis="0 0 -1" pos="0 0 0" limited="true" range="-3.5 3.5"/>

                        <body name="gearbox2_2" pos="0.001 0 0" euler="3.141592 0 0">
                    <geom name="gearbox2_2" type="mesh" mesh="gearbox2" pos="0 0 0" material="petg" />
                    <inertial pos="-0.003597 0 -0.0571" mass="0.549677" fullinertia="0.002354 0.002182 0.0003883 0.000000138325 -0.0001131 -0.00000158513"/>
                        <body name="encoder_1_2" pos="-0.0298 0 -0.0571" euler="0 -1.5707963 0 ">
                    <geom name="encoder_1_2" type="mesh" mesh="encoder" pos="0 0 0" material="pcb" />
                    <inertial pos="0 0 0.006" mass="0.008" fullinertia="0.00000665976 0.000014054247 0.000014432848 -0.000000796234 -0.000003221775 -0.000000490008"/>
                        <body name="spacer_0_2" pos="0 0 -0.1242" euler="0 0 0">
                    <geom type="box" size="0.0001 0.00001 0.0001" rgba=".9 .9 .9 1"/>
                    <inertial pos="0 0 0" mass="0.001" fullinertia="0.00000665976 0.000014054247 0.000014432848 -0.000000796234 -0.000003221775 -0.000000490008"/>


                        <body name="gearbox_3_2" pos="0 0 0" euler="3.141592 0 1.570796">
                    <geom name="gearbox_3_2" type="mesh" mesh="gearbox_3" pos="0 0 0" material="petg"/>
                    <inertial pos="0 0 0.03062" mass="0.549677" fullinertia="0.0008966 0.0008969 0.0005599 -0.000000208093 0.000000039236 -0.000000146242"/>

                    <joint name="joint2_2" axis="0 0 -1" pos="0 0 0" limited="true" range="-3.3 3.3"/>

                        <body name="upper_leg_2" pos="0 0 0.023" euler="0 0 0">
                    <geom name="upper_leg_2" type="mesh" mesh="upper_leg" pos="0 0 0" material="aluminium"/>
                    <inertial pos="-0.065247 0 -0.012792" mass="0.113615" fullinertia="0.000037213733 0.0008028 0.0007791 0.000000319788 -0.000092327798 0.000000061466"/>
                         <body name="upper_leg_belt_2" pos="0 0 0" euler="0 0 0">
                    <geom name="upper_leg_belt_2" type="mesh" mesh="upper_leg_belt" pos="0 0 0" material="carbon"/>
                    <inertial pos="-0.077 0 -0.012" mass="0.03" fullinertia="0.000037213733 0.0008028 0.0007791 0.000000319788 -0.000092327798 0.000000061466"/>
                        <body name="spacer_1_2" pos="-0.1567 0 -0.021" euler="0 3.141592 0">
                    <geom type="box" size="0.0001 0.00001 0.0001" rgba=".9 .9 .9 1"/>
                    <inertial pos="0 0 0" mass="0.001" fullinertia="0.00000665976 0.000014054247 0.000014432848 -0.000000796234 -0.000003221775 -0.000000490008"/>

                    <joint name="joint3_2" axis="0 0 -1" pos="0 0 0" limited="true" range="-2.5 2.5"/>

                        <body name="lower_leg_2" pos="0 0 0" euler="0 0 0">
                    <geom name="lower_leg_2" type="mesh" mesh="lower_leg" pos="0 0 0" material="aluminium" />
                    <inertial pos="0.0733980 0.0000000 -0.0084740" mass="0.0445630" fullinertia="0.0000060 0.0003640 0.0003596 0.0000002 0.0000276 0.0000000"/>

                        </body>
                        </body>
                        </body>
                        </body>
                        </body>
                        </body>
                        </body>
                        </body>
                        </body>
                        </body>
                        </body>
		                </body>


                             <!-- leg 3 -->
                        <body name="encoder_0_3" pos="0.0164 -0.11 0.0273" euler="1.570796 3.141592 0">
                    <geom name="encoder_0_3" type="mesh" mesh="encoder" pos="0 0 0" material="pcb" />
                    <inertial pos="0 0 0.006" mass="0.008" fullinertia="0.00000665976 0.000014054247 0.000014432848 -0.000000796234 -0.000003221775 -0.000000490008"/>
                        <body name="gearbox_1_3" pos="0 0 -0.056" euler="0 0 0">
                    <inertial pos="0 0 0.03062" mass="0.549677" fullinertia="0.0008966 0.0008969 0.0005599 -0.000000208093 0.000000039236 -0.000000146242"/>
                    <geom name="gearbox_1_3" type="mesh" mesh="gearbox_1" pos="0 0 0" material="petg"/>
                        <body name="gearbox1_spacer_3" pos="0 0.0 -0.012" euler="0 0 0">
                    <geom name="gearbox1_spacer_3" type="mesh" mesh="gearbox1_spacer" pos="0 0 0" material="petg"/>
                    <inertial pos="0 0 0.006" mass="0.008" fullinertia="0.00000665976 0.000014054247 0.000014432848 -0.000000796234 -0.000003221775 -0.000000490008"/>
                        <body name="spacer_3_3" pos="0.002 0 -0.0003" euler="0 3.141592 0">
                    <geom type="box" size="0.0001 0.00001 0.0001" rgba=".9 .9 .9 1"/>
                    <inertial pos="0 0 0" mass="0.001" fullinertia="0.00000665976 0.000014054247 0.000014432848 -0.000000796234 -0.000003221775 -0.000000490008"/>

                    <joint name="joint0_3" axis="0 0 -1" pos="0 0 0" limited="true" range="-3.5 3.5"/>

                        <body name="gearbox2_3" pos="0.001 0 0" euler="3.141592 0 3.141592">
                    <geom name="gearbox2_3" type="mesh" mesh="gearbox2" pos="0 0 0" material="petg" />
                    <inertial pos="-0.003597 0 -0.0571" mass="0.549677" fullinertia="0.002354 0.002182 0.0003883 0.000000138325 -0.0001131 -0.00000158513"/>
                        <body name="encoder_1_3" pos="-0.0298 0 -0.0571" euler="0 -1.5707963 0 ">
                    <geom name="encoder_1_3" type="mesh" mesh="encoder" pos="0 0 0" material="pcb" />
                    <inertial pos="0 0 0.006" mass="0.008" fullinertia="0.00000665976 0.000014054247 0.000014432848 -0.000000796234 -0.000003221775 -0.000000490008"/>
                        <body name="spacer_0_3" pos="0 0 -0.1242" euler="0 0 0">
                    <geom type="box" size="0.0001 0.00001 0.0001" rgba=".9 .9 .9 1"/>
                    <inertial pos="0 0 0" mass="0.001" fullinertia="0.00000665976 0.000014054247 0.000014432848 -0.000000796234 -0.000003221775 -0.000000490008"/>


                        <body name="gearbox_3_3" pos="0 0 0" euler="3.141592 0 -1.570796">
                    <geom name="gearbox_3_3" type="mesh" mesh="gearbox_3" pos="0 0 0" material="petg"/>
                    <inertial pos="0 0 0.03062" mass="0.549677" fullinertia="0.0008966 0.0008969 0.0005599 -0.000000208093 0.000000039236 -0.000000146242"/>

                    <joint name="joint2_3" axis="0 0 -1" pos="0 0 0" limited="true" range="-3.3 3.3"/>

                        <body name="upper_leg_3" pos="0 0 0.023" euler="0 0 0">
                    <geom name="upper_leg_3" type="mesh" mesh="upper_leg" pos="0 0 0" material="aluminium"/>
                    <inertial pos="-0.065247 0 -0.012792" mass="0.113615" fullinertia="0.000037213733 0.0008028 0.0007791 0.000000319788 -0.000092327798 0.000000061466"/>
                         <body name="upper_leg_belt_3" pos="0 0 0" euler="0 0 0">
                    <geom name="upper_leg_belt_3" type="mesh" mesh="upper_leg_belt" pos="0 0 0" material="carbon"/>
                    <inertial pos="-0.077 0 -0.012" mass="0.03" fullinertia="0.000037213733 0.0008028 0.0007791 0.000000319788 -0.000092327798 0.000000061466"/>
                        <body name="spacer_1_3" pos="-0.1567 0 -0.021" euler="0 3.141592 0">
                    <geom type="box" size="0.0001 0.00001 0.0001" rgba=".9 .9 .9 1"/>
                    <inertial pos="0 0 0" mass="0.001" fullinertia="0.00000665976 0.000014054247 0.000014432848 -0.000000796234 -0.000003221775 -0.000000490008"/>

                    <joint name="joint3_3" axis="0 0 -1" pos="0 0 0" limited="true" range="-2.5 2.5"/>

                        <body name="lower_leg_3" pos="0 0 0" euler="0 0 0">
                    <geom name="lower_leg_3" type="mesh" mesh="lower_leg" pos="0 0 0" material="aluminium" />
                    <inertial pos="0.0733980 0.0000000 -0.0084740" mass="0.0445630" fullinertia="0.0000060 0.0003640 0.0003596 0.0000002 0.0000276 0.0000000"/>

                        </body>
                        </body>
                        </body>
                        </body>
                        </body>
                        </body>
                        </body>
                        </body>
                        </body>
                        </body>
                        </body>
		                </body>

                            </body>



                            <!-- leg 2 -->
                        <body name="encoder_0_1" pos="-0.1227 0.094 0.021" euler="1.570796 0 0">
                    <geom name="encoder_0_1" type="mesh" mesh="encoder" pos="0 0 0" material="pcb" />
                    <inertial pos="0 0 0.006" mass="0.008" fullinertia="0.00000665976 0.000014054247 0.000014432848 -0.000000796234 -0.000003221775 -0.000000490008"/>
                        <body name="gearbox_1_1" pos="0 0 -0.056" euler="0 0 0">
                    <inertial pos="0 0 0.03062" mass="0.549677" fullinertia="0.0008966 0.0008969 0.0005599 -0.000000208093 0.000000039236 -0.000000146242"/>
                    <geom name="gearbox_1_1" type="mesh" mesh="gearbox_1" pos="0 0 0" material="petg"/>
                        <body name="gearbox1_spacer_1" pos="0 0.0 -0.012" euler="0 0 0">
                    <geom name="gearbox1_spacer_1" type="mesh" mesh="gearbox1_spacer" pos="0 0 0" material="petg"/>
                    <inertial pos="0 0 0.006" mass="0.008" fullinertia="0.00000665976 0.000014054247 0.000014432848 -0.000000796234 -0.000003221775 -0.000000490008"/>
                        <body name="spacer_3_1" pos="0.002 0 -0.0003" euler="0 3.141592 0">
                    <geom type="box" size="0.0001 0.00001 0.0001" rgba=".9 .9 .9 1"/>
                    <inertial pos="0 0 0" mass="0.001" fullinertia="0.00000665976 0.000014054247 0.000014432848 -0.000000796234 -0.000003221775 -0.000000490008"/>

                    <joint name="joint0_1" axis="0 0 -1" pos="0 0 0" limited="true" range="-3.5 3.5"/>

                        <body name="gearbox2_1" pos="0.001 0 0" euler="3.141592 0 0">
                    <geom name="gearbox2_1" type="mesh" mesh="gearbox2" pos="0 0 0" material="petg" />
                    <inertial pos="-0.003597 0 -0.0571" mass="0.549677" fullinertia="0.002354 0.002182 0.0003883 0.000000138325 -0.0001131 -0.00000158513"/>
                        <body name="encoder_1_1" pos="-0.0298 0 -0.0571" euler="0 -1.5707963 0 ">
                    <geom name="encoder_1_1" type="mesh" mesh="encoder" pos="0 0 0" material="pcb" />
                    <inertial pos="0 0 0.006" mass="0.008" fullinertia="0.00000665976 0.000014054247 0.000014432848 -0.000000796234 -0.000003221775 -0.000000490008"/>
                        <body name="spacer_0_1" pos="0 0 -0.1242" euler="0 0 0">
                    <geom type="box" size="0.0001 0.00001 0.0001" rgba=".9 .9 .9 1"/>
                    <inertial pos="0 0 0" mass="0.001" fullinertia="0.00000665976 0.000014054247 0.000014432848 -0.000000796234 -0.000003221775 -0.000000490008"/>


                        <body name="gearbox_3_1" pos="0 0 0" euler="3.141592 0 1.570796">
                    <geom name="gearbox_3_1" type="mesh" mesh="gearbox_3" pos="0 0 0" material="petg"/>
                    <inertial pos="0 0 0.03062" mass="0.549677" fullinertia="0.0008966 0.0008969 0.0005599 -0.000000208093 0.000000039236 -0.000000146242"/>

                    <joint name="joint2_1" axis="0 0 -1" pos="0 0 0" limited="true" range="-3.3 3.3"/>

                        <body name="upper_leg_1" pos="0 0 0.023" euler="0 0 0">
                    <geom name="upper_leg_1" type="mesh" mesh="upper_leg" pos="0 0 0" material="aluminium"/>
                    <inertial pos="-0.065247 0 -0.012792" mass="0.113615" fullinertia="0.000037213733 0.0008028 0.0007791 0.000000319788 -0.000092327798 0.000000061466"/>
                         <body name="upper_leg_belt_1" pos="0 0 0" euler="0 0 0">
                    <geom name="upper_leg_belt_1" type="mesh" mesh="upper_leg_belt" pos="0 0 0" material="carbon"/>
                    <inertial pos="-0.077 0 -0.012" mass="0.03" fullinertia="0.000037213733 0.0008028 0.0007791 0.000000319788 -0.000092327798 0.000000061466"/>
                        <body name="spacer_1_1" pos="-0.1567 0 -0.021" euler="0 3.141592 0">
                    <geom type="box" size="0.0001 0.00001 0.0001" rgba=".9 .9 .9 1"/>
                    <inertial pos="0 0 0" mass="0.001" fullinertia="0.00000665976 0.000014054247 0.000014432848 -0.000000796234 -0.000003221775 -0.000000490008"/>

                    <joint name="joint3_1" axis="0 0 -1" pos="0 0 0" limited="true" range="-2.5 2.5"/>

                        <body name="lower_leg_1" pos="0 0 0" euler="0 0 0">
                    <geom name="lower_leg_1" type="mesh" mesh="lower_leg" pos="0 0 0" material="aluminium" />
                    <inertial pos="0.0733980 0.0000000 -0.0084740" mass="0.0445630" fullinertia="0.0000060 0.0003640 0.0003596 0.0000002 0.0000276 0.0000000"/>

                        </body>
                        </body>
                        </body>
                        </body>
                        </body>
                        </body>
                        </body>
                        </body>
                        </body>
                        </body>
                        </body>
		                </body>




                             <!-- leg 1 -->
                        <body name="encoder_0_4" pos="-0.0168 0.094 0.021" euler="1.570796 0 0">
                    <geom name="encoder_0_4" type="mesh" mesh="encoder" pos="0 0 0" material="pcb" />
                    <inertial pos="0 0 0.006" mass="0.008" fullinertia="0.00000665976 0.000014054247 0.000014432848 -0.000000796234 -0.000003221775 -0.000000490008"/>
                        <body name="gearbox_1_4" pos="0 0 -0.056" euler="0 0 0">
                    <inertial pos="0 0 0.03062" mass="0.549677" fullinertia="0.0008966 0.0008969 0.0005599 -0.000000208093 0.000000039236 -0.000000146242"/>
                    <geom name="gearbox_1_4" type="mesh" mesh="gearbox_1" pos="0 0 0" material="petg"/>
                        <body name="gearbox1_spacer_4" pos="0 0.0 -0.012" euler="0 0 0">
                    <geom name="gearbox1_spacer_4" type="mesh" mesh="gearbox1_spacer" pos="0 0 0" material="petg"/>
                    <inertial pos="0 0 0.006" mass="0.008" fullinertia="0.00000665976 0.000014054247 0.000014432848 -0.000000796234 -0.000003221775 -0.000000490008"/>
                        <body name="spacer_3_4" pos="0.002 0 -0.0003" euler="0 3.141592 0">
                    <geom type="box" size="0.0001 0.00001 0.0001" rgba=".9 .9 .9 1"/>
                    <inertial pos="0 0 0" mass="0.001" fullinertia="0.00000665976 0.000014054247 0.000014432848 -0.000000796234 -0.000003221775 -0.000000490008"/>

                    <joint name="joint0_4" axis="0 0 -1" pos="0 0 0" limited="true" range="-3.5 3.5"/>

                        <body name="gearbox2_4" pos="0.001 0 0" euler="3.141592 0 3.141592">
                    <geom name="gearbox2_4" type="mesh" mesh="gearbox2" pos="0 0 0" material="petg" />
                    <inertial pos="-0.003597 0 -0.0571" mass="0.549677" fullinertia="0.002354 0.002182 0.0003883 0.000000138325 -0.0001131 -0.00000158513"/>
                        <body name="encoder_1_4" pos="-0.0298 0 -0.0571" euler="0 -1.5707963 0 ">
                    <geom name="encoder_1_4" type="mesh" mesh="encoder" pos="0 0 0" material="pcb" />
                    <inertial pos="0 0 0.006" mass="0.008" fullinertia="0.00000665976 0.000014054247 0.000014432848 -0.000000796234 -0.000003221775 -0.000000490008"/>
                        <body name="spacer_0_4" pos="0 0 -0.1242" euler="0 0 0">
                    <geom type="box" size="0.0001 0.00001 0.0001" rgba=".9 .9 .9 1"/>
                    <inertial pos="0 0 0" mass="0.001" fullinertia="0.00000665976 0.000014054247 0.000014432848 -0.000000796234 -0.000003221775 -0.000000490008"/>


                        <body name="gearbox_3_4" pos="0 0 0" euler="3.141592 0 -1.570796">
                    <geom name="gearbox_3_4" type="mesh" mesh="gearbox_3" pos="0 0 0" material="petg"/>
                    <inertial pos="0 0 0.03062" mass="0.549677" fullinertia="0.0008966 0.0008969 0.0005599 -0.000000208093 0.000000039236 -0.000000146242"/>

                    <joint name="joint2_4" axis="0 0 -1" pos="0 0 0" limited="true" range="-3.3 3.3"/>

                        <body name="upper_leg_4" pos="0 0 0.023" euler="0 0 0">
                    <geom name="upper_leg_4" type="mesh" mesh="upper_leg" pos="0 0 0" material="aluminium"/>
                    <inertial pos="-0.065247 0 -0.012792" mass="0.113615" fullinertia="0.000037213733 0.0008028 0.0007791 0.000000319788 -0.000092327798 0.000000061466"/>
                         <body name="upper_leg_belt_4" pos="0 0 0" euler="0 0 0">
                    <geom name="upper_leg_belt_4" type="mesh" mesh="upper_leg_belt" pos="0 0 0" material="carbon"/>
                    <inertial pos="-0.077 0 -0.012" mass="0.03" fullinertia="0.000037213733 0.0008028 0.0007791 0.000000319788 -0.000092327798 0.000000061466"/>
                        <body name="spacer_1_4" pos="-0.1567 0 -0.021" euler="0 3.141592 0">
                    <geom type="box" size="0.0001 0.00001 0.0001" rgba=".9 .9 .9 1"/>
                    <inertial pos="0 0 0" mass="0.001" fullinertia="0.00000665976 0.000014054247 0.000014432848 -0.000000796234 -0.000003221775 -0.000000490008"/>

                    <joint name="joint3_4" axis="0 0 -1" pos="0 0 0" limited="true" range="-2.5 2.5"/>

                        <body name="lower_leg_4" pos="0 0 0" euler="0 0 0">
                    <geom name="lower_leg_4" type="mesh" mesh="lower_leg" pos="0 0 0" material="aluminium" />
                    <inertial pos="0.0733980 0.0000000 -0.0084740" mass="0.0445630" fullinertia="0.0000060 0.0003640 0.0003596 0.0000002 0.0000276 0.0000000"/>

                        </body>
                        </body>
                        </body>
                        </body>
                        </body>
                        </body>
                        </body>
                        </body>
                        </body>
                        </body>
                        </body>
		                </body>


</body>
    </worldbody>

<actuator>
    <motor name="0_0" joint="joint0_2" />
    <motor name="0_1" joint="joint2_2"/>

    <motor name="motor_0_2" joint="joint3_2" />
    <position name="position_0_2" joint="joint3_2" kp="0"/>
    <velocity name="velocity_0_2" joint="joint3_2" kv="0"/>

    <motor name="1_3" joint="joint0_4"/>
    <motor name="1_4" joint="joint2_4"/>
    <motor name="1_5" joint="joint3_4"/>

    <motor name="2_6" joint="joint0_1"/>
    <motor name="2_7" joint="joint2_1"/>
    <motor name="2_8" joint="joint3_1"/>

    <motor name="3_0" joint="joint0_3"/>
    <motor name="3_10" joint="joint2_3"/>
    <motor name="3_11" joint="joint3_3"/>


</actuator>

</mujoco>